# Обробка винятків


Модель винятків **(exceptions)** в PHP 5 простіша, ніж в інших мовах програмування. Виняток можна згенерувати (як кажуть, "викинути") за допомогою оператора throw, і можна перехопити (або, як кажуть, "піймати") оператором catch. Код, що викидає виключення, повинен бути оточений блоком try, для того щоб можна було перехопити виняток. Кожен блок try повинен мати як мінімум один відповідний блок catch. Так само можна використовувати кілька блоків catch, що перехоплюють різні класи винятків. Нормальне виконання буде продовжено за останнім блоком catch. Винятки так само можуть бути згенерованими (або перегереровані - тобто викинуті знову) оператором throw всередині блоку catch.

При генерації виключення, код який слідує нижче оператора throw виконаний не буде, а PHP зробить спробу знайти перший блок catch, що перехоплює виключення даного класу. Якщо виключення не буде перехоплено, PHP видасть повідомлення про помилку: "Uncaught Exception ..." (неперехоплений виняток), якщо звичайно не був визначений обробник помилок за допомогою функції set_exception_handler ().

**Приклад № 1** Викид винятків


```php
<?php
function inverse($x)
{
    if (!$x) {
        throw new Exception("Поділ на нуль.");
    } else {
        return 1 / $x;
    }
}

try {
    echo inverse(5) . "\n";
    echo inverse(0) . "\n";
} catch (Exception $e) {
    echo "Викинуто виняток:", $e->getMessage(), "\n";
}

echo "Hello World";
?>
```


Результат виконання цього прикладу:

0.2

Викинуто виняток: Поділ на нуль.

Hello World

## Спадкування винятків

Обробник винятків користувача повинен бути визначений, як клас, що розширює вбудований клас Exception. Нижче наведено методи і властивості класу Exception, доступні дочірнім класам.

**Приклад № 1** Вбудований клас Exception


```php
<?php 
class Exception 
{ 
protected $message = 'Unknown exception'; // повідомлення 
protected $code = 0; // Код винятку, визначається користувачем 
protected $file; // файл у якому було викинуто виключення 
protected $line; // рядок у якому було викинуто виключення 

function __construct ($message = null, $code = 0); 

final function getMessage (); // Повертає повідомлення виключення 
final function getCode (); // Код винятку 
final function getFile (); // Файл, де викинуто виняток 
final function getLine (); // Рядок, що викинув виключення 
final function getTrace (); // Масив backtrace () 
final function getTraceAsString (); // Зворотнє трасування, як рядок

function __toString (); /* повинен повернути форматований рядок,для відображення */
}
?>
```


Якщо клас, успадкований від Exception перевизначає конструктор, необхідно викликати в конструкторі `parent::__construct ()`, щоб бути впевненим, що всі дані будуть доступні. Метод `__toString ()` може бути перевизначений, що б забезпечити потрібний вивід, коли об'єкт перетворюється в рядок.

*Приклад № 2* Успадкування класу Exception


```php
<?php
/* Визначимо свій клас винятку*/
class MyException extends Exception
{
    // Перевизначивши виняток так, що параметр message стане обов'язковим
    public function __construct($message, $code = 0)
    {
        // Якийсь код

        parent::__construct($message, $code);
    }

    // Перевизначаємо рядкове подання об'єкта.
    public function __toString()
    {
        return __CLASS__ . ": [{$this->code}]: {$this->message} \n";
    }

    public function customFunction()
    {
        echo "Ми можемо визначати нові методи в успадкованому класі \n";
    }
}

/* Створимо клас для тестування винятку */
class TestException
{
    public $var;

    const THROW_NONE = 0;
    const THROW_CUSTOM = 1;
    const THROW_DEFAULT = 2;

    function __construct($avalue = self::THROW_NONE)
    {
        switch ($avalue) {
            case self::THROW_CUSTOM:
                // Генеруємо власне виключення
                throw new MyException("1 - неправильний параметр ", 5);
                break;

            case self::THROW_DEFAULT:
                // Генеруємо вбудований виняток
                throw new Exception("2 - неприпустимий параметр ", 6);
                break;

            default:
                // Ніяких винятків, об'єкт буде створений.
                $tHIS->var = $avalue;
                break;
        }
    }
}

// Приклад 1
try {
    $o = new TestException(TestException::THROW_CUSTOM);
} catch (MyException $e) {
    // Буде перехоплено
    echo "Злови власне, перевизначене виключення \n", $e;
    $e->customFunction();
} catch (Exception $e) {
    // Буде пропущено.
    echo "Злови вбудоване виключення \n", $e;
}

// Звідси буде продовжено виконання програми
var_dump($o);
echo "\n\n";

// Приклад 2
try {
    $o = new TestException(TestException::THROW_DEFAULT);
} catch (MyException $e) {
    // Тип винятку не співпаде
    echo "Злови перевизначене виключення \n", $e;
    $e->customFunction();
} catch (Exception $e) {
    // Буде перехоплено
    echo "перехоплено вбудоване виключення \n", $e;
}

// Звідси буде продовжено виконання програми
var_dump($o);
echo "\n\n";

// Приклад 3
try {
    $o = new TestException(TestException::THROW_CUSTOM);
} catch (Exception $e) {
    // Буде перехоплено.
    echo "Злови вбудоване виключення \n", $e;
}

// Продовження виконання програми
var_dump($o);
echo "\n\n";

// Приклад 4
try {
    $o = new TestException();
} catch (Exception $e) {
    // Буде пропущено, тому що виняток не викинеться
    echo "Злови вбудоване виключення \n", $e;
}

// Продовження виконання програми
var_dump($o);
echo "\n\n";
?>
```
